<mujoco model="Snake">
  <compiler angle="degree" coordinate="local" inertiafromgeom="true" meshdir="tr_stl_files"/>
  <option collision="predefined" integrator="RK4" timestep="0.002" />
  <default>
    <geom conaffinity="1" condim="1" contype="1" material="geom"/>
    <joint armature='0.1'/>
    <pair condim="3" friction="0.5 0.5" solimp="0.9 0.95 0.001 0.9 6" solref= "0.02 1"/>
  </default>
  <asset>
    <texture builtin="gradient" height="100" rgb1="1 1 1" rgb2="0 0 0" type="skybox" width="100"/>
    <texture builtin="flat" height="1278" mark="cross" markrgb="1 1 1" name="texgeom" random="0.01" rgb1="0.8 0.6 0.4" rgb2="0.8 0.6 0.4" type="cube" width="127"/>
    <texture builtin="checker" height="100" name="texplane" rgb1="0 0 0" rgb2="0.8 0.8 0.8" type="2d" width="100"/>
    <material name="MatPlane" reflectance="0.5" shininess="1" specular="1" texrepeat="30 30" texture="texplane"/>
    <material name="geom" texture="texgeom" texuniform="true"/>
    <mesh file="servo_arm_connector_v1.stl" scale=".001 .001 .001" name="arm_connector_mesh"/>
    <mesh file="servo_back_connector_v1.stl" scale=".001 .001 .001" name="back_connector_mesh" />
    <mesh file="motor.stl" scale=".001 .001 .001" name="motor_mesh" />
  </asset>
  <contact>
     <pair name="g1" geom1="caps1" geom2="floor" />
     <pair name="g2" geom1="caps2" geom2="floor" />
     <pair name="g3" geom1="caps3" geom2="floor" />
     <pair name="g4" geom1="caps4" geom2="floor" />
     <pair name="g5" geom1="caps5" geom2="floor" />
     <pair name="g6" geom1="caps6" geom2="floor" />
     <pair name="g7" geom1="caps7" geom2="floor" />
     <pair name="g8" geom1="caps8" geom2="floor" />
  </contact>
  <worldbody>
    <light cutoff="100" diffuse="1 1 1" dir="-0 0 -1.3" directional="true" exponent="1" pos="0 0 0.13" specular=".1 .1 .1"/>
    <geom conaffinity="1" condim="3" material="MatPlane" name="floor" pos="0 0 -0.01" rgba="0.8 0.9 0.8 1" size="10 10 0.1" type="plane"/>

    <!--  ================= SNAKE ================= /-->
  
    <!-- head/seg1 -->
    <body name="seg1" pos="0 0 .040">
      <camera name="track" mode="trackcom" pos="-.5 -2.5 2.5" xyaxes="1 0 0 0 1 1"/>
      <geom name="seg1_body_layer0" type="box" size="0.05 0.0350 0.004" density="56.268" pos="-0.0665 0 -0.0157" rgba="0.9 0.7 .1 1"/>
      <geom name="seg1_body_layer1" type="box" size="0.05 0.0145 0.024" density="56.268" pos="-0.0665 0 0.012" rgba="0.9 0.7 .1 1"/>
      <geom mesh="arm_connector_mesh" type="mesh" mass="0.027" euler="180 0 -90" pos="-0.133 0 0.0005" rgba="0.7 0.2 .1 1"/>
      <geom name="caps1" type="capsule" size="0.004" fromto="-0.022 0 -0.018  -0.111 0 -0.018" mass="0.0000001" rgba="0 0 0 1"/>
      <joint axis="1 0 0" name="slider1" pos="-0.015 0 0" type="slide"/>
      <joint axis="0 1 0" name="slider2" pos="-0.015 0 0" type="slide"/>
      <joint axis="0 0 1" name="slider3" pos="-0.015 0 0" type="slide"/>
      <joint axis="0 0 1" name="free_body_rot" pos="-0.015 0 0" type="hinge"/>
      
      <!-- Segment 2 -->
      <body name="seg2" pos="-0.167 0 0">
        <geom name="seg2_body_layer0" type="box" size="0.05 0.0350 0.004" density="56.268" pos="-0.0665 0 -0.0157" rgba="0.9 0.7 .1 1"/>
        <geom name="seg2_body_layer1" type="box" size="0.05 0.0145 0.024" density="56.268" pos="-0.0665 0 0.012" rgba="0.9 0.7 .1 1"/>
        <geom mesh="back_connector_mesh" type="mesh" mass="0.027" euler="180 0 -90" pos="0.035 0 0.0005" rgba="0.1 0.7 .2 1"/>
        <geom mesh="arm_connector_mesh" type="mesh" mass="0.027" euler="180 0 -90" pos="-0.133 0 0.0005" rgba="0.7 0.2 .1 1"/>
        <geom mesh="motor_mesh" type="mesh" mass="0.0572" euler="0 0 -90" pos="0.023 0 0.011" rgba=".1 .1 1 1"/>
        <geom name="caps2" type="capsule" size="0.004" fromto="-0.022 0 -0.018  -0.111 0 -0.018" mass="0.0000001" rgba="0 0 0 1"/>
        <joint axis="0 0 1" limited="true" name="motor1_rot" pos="0.0225 0 0" range="-80 80" type="hinge"/>

        <!-- Segment 3 -->
        <body name="seg3" pos="-0.167 0 0">
          <geom name="seg3_body_layer0" type="box" size="0.05 0.0350 0.004" density="56.268" pos="-0.0665 0 -0.0157" rgba="0.9 0.7 .1 1"/>
          <geom name="seg3_body_layer1" type="box" size="0.05 0.0145 0.024" density="56.268" pos="-0.0665 0 0.012" rgba="0.9 0.7 .1 1"/>
          <geom mesh="back_connector_mesh" type="mesh" mass="0.027" euler="180 0 -90" pos="0.035 0 0.0005" rgba="0.1 0.7 .2 1"/>
          <geom mesh="arm_connector_mesh" type="mesh" mass="0.027" euler="180 0 -90" pos="-0.133 0 0.0005" rgba="0.7 0.2 .1 1"/>
          <geom mesh="motor_mesh" type="mesh" mass="0.0572" euler="0 0 -90" pos="0.023 0 0.011" rgba=".1 .1 1 1"/>
          <geom name="caps3" type="capsule" size="0.004" fromto="-0.022 0 -0.018  -0.111 0 -0.018" mass="0.0000001" rgba="0 0 0 1"/>
          <joint axis="0 0 1" limited="true" name="motor2_rot" pos="0.0225 0 0" range="-80 80" type="hinge"/>

          <!-- Segment 4 -->
          <body name="seg4" pos="-0.167 0 0">
            <geom name="seg4_body_layer0" type="box" size="0.05 0.0350 0.004" density="56.268" pos="-0.0665 0 -0.0157" rgba="0.9 0.7 .1 1"/>
            <geom name="seg4_body_layer1" type="box" size="0.05 0.0145 0.024" density="56.268" pos="-0.0665 0 0.012" rgba="0.9 0.7 .1 1"/>
            <geom mesh="back_connector_mesh" type="mesh" mass="0.027" euler="180 0 -90" pos="0.035 0 0.0005" rgba="0.1 0.7 .2 1"/>
            <geom mesh="arm_connector_mesh" type="mesh" mass="0.027" euler="180 0 -90" pos="-0.133 0 0.0005" rgba="0.7 0.2 .1 1"/>
            <geom mesh="motor_mesh" type="mesh" mass="0.0572" euler="0 0 -90" pos="0.023 0 0.011" rgba=".1 .1 1 1"/>
            <geom name="caps4" type="capsule" size="0.004" fromto="-0.022 0 -0.018  -0.111 0 -0.018" mass="0.0000001" rgba="0 0 0 1"/>
            <joint axis="0 0 1" limited="true" name="motor3_rot" pos="0.0225 0 0" range="-80 80" type="hinge"/>

            <!-- Segment 5 -->
            <body name="seg5" pos="-0.167 0 0">
              <geom name="seg5_body_layer0" type="box" size="0.05 0.0350 0.004" density="56.268" pos="-0.0665 0 -0.0157" rgba="0.9 0.7 .1 1"/>
              <geom name="seg5_body_layer1" type="box" size="0.05 0.0145 0.024" density="56.268" pos="-0.0665 0 0.012" rgba="0.9 0.7 .1 1"/>
              <geom mesh="back_connector_mesh" type="mesh" mass="0.027" euler="180 0 -90" pos="0.035 0 0.0005" rgba="0.1 0.7 .2 1"/>
              <geom mesh="arm_connector_mesh" type="mesh" mass="0.027" euler="180 0 -90" pos="-0.133 0 0.0005" rgba="0.7 0.2 .1 1"/>
              <geom mesh="motor_mesh" type="mesh" mass="0.0572" euler="0 0 -90" pos="0.023 0 0.011" rgba=".1 .1 1 1"/>
              <geom name="caps5" type="capsule" size="0.004" fromto="-0.022 0 -0.018  -0.111 0 -0.018" mass="0.0000001" rgba="0 0 0 1"/>
              <joint axis="0 0 1" limited="true" name="motor4_rot" pos="0.0225 0 0" range="-80 80" type="hinge"/>

              <!-- Segment 6 -->
              <body name="seg6" pos="-0.167 0 0">
                <geom name="seg6_body_layer0" type="box" size="0.05 0.0350 0.004" density="56.268" pos="-0.0665 0 -0.0157" rgba="0.9 0.7 .1 1"/>
                <geom name="seg6_body_layer1" type="box" size="0.05 0.0145 0.024" density="56.268" pos="-0.0665 0 0.012" rgba="0.9 0.7 .1 1"/>
                <geom mesh="back_connector_mesh" type="mesh" mass="0.027" euler="180 0 -90" pos="0.035 0 0.0005" rgba="0.1 0.7 .2 1"/>
                <geom mesh="arm_connector_mesh" type="mesh" mass="0.027" euler="180 0 -90" pos="-0.133 0 0.0005" rgba="0.7 0.2 .1 1"/>
                <geom mesh="motor_mesh" type="mesh" mass="0.0572" euler="0 0 -90" pos="0.023 0 0.011" rgba=".1 .1 1 1"/>
                <geom name="caps6" type="capsule" size="0.004" fromto="-0.022 0 -0.018  -0.111 0 -0.018" mass="0.0000001" rgba="0 0 0 1"/>
                <joint axis="0 0 1" limited="true" name="motor5_rot" pos="0.0225 0 0" range="-80 80" type="hinge"/>

                <!-- Segment 7 -->
                <body name="seg7" pos="-0.167 0 0">
                  <geom name="seg7_body_layer0" type="box" size="0.05 0.0350 0.004" density="56.268" pos="-0.0665 0 -0.0157" rgba="0.9 0.7 .1 1"/>
                  <geom name="seg7_body_layer1" type="box" size="0.05 0.0145 0.024" density="56.268" pos="-0.0665 0 0.012" rgba="0.9 0.7 .1 1"/>
                  <geom mesh="back_connector_mesh" type="mesh" mass="0.027" euler="180 0 -90" pos="0.035 0 0.0005" rgba="0.1 0.7 .2 1"/>
                  <geom mesh="arm_connector_mesh" type="mesh" mass="0.027" euler="180 0 -90" pos="-0.133 0 0.0005" rgba="0.7 0.2 .1 1"/>
                  <geom mesh="motor_mesh" type="mesh" mass="0.0572" euler="0 0 -90" pos="0.023 0 0.011" rgba=".1 .1 1 1"/>
                  <geom name="caps7" type="capsule" size="0.004" fromto="-0.022 0 -0.018  -0.111 0 -0.018" mass="0.0000001" rgba="0 0 0 1"/>
                  <joint axis="0 0 1" limited="true" name="motor6_rot" pos="0.0225 0 0" range="-80 80" type="hinge"/>

                  <!-- Segment 8 -->
                  <body name="seg8" pos="-0.167 0 0">
                    <geom name="seg8_body_layer0" type="box" size="0.05 0.0350 0.004" density="56.268" pos="-0.0665 0 -0.0157" rgba="0.9 0.7 .1 1"/>
                    <geom name="seg8_body_layer1" type="box" size="0.05 0.0145 0.024" density="56.268" pos="-0.0665 0 0.012" rgba="0.9 0.7 .1 1"/>
                    <geom mesh="back_connector_mesh" type="mesh" mass="0.027" euler="180 0 -90" pos="0.035 0 0.0005" rgba="0.1 0.7 .2 1"/>
                    <geom mesh="motor_mesh" type="mesh" mass="0.0572" euler="0 0 -90" pos="0.023 0 0.011" rgba=".1 .1 1 1"/>
                    <geom name="caps8" type="capsule" size="0.004" fromto="-0.022 0 -0.018  -0.111 0 -0.018" mass="0.0000001" rgba="0 0 0 1"/>
                    <joint axis="0 0 1" limited="true" name="motor7_rot" pos="0.0225 0 0" range="-80 80" type="hinge"/> 
                  </body>
                </body>
              </body>
            </body>
          </body>
        </body>
      </body>
    </body>
    <body name="goal_sphere_body1" pos="2 2 0"> 
      <geom name="goal_sphere1" type="sphere" size="0.1" mass="1e10" conaffinity="0" contype="0" rgba="1 0 0 .5"/>
    </body>
  </worldbody>

  <actuator>
    <!-- ACTUATION -->
    <motor ctrllimited="true" ctrlrange="-1 1"  gear="1"  joint="motor1_rot"/>
    <motor ctrllimited="true" ctrlrange="-1 1"  gear="1"  joint="motor2_rot"/>
    <motor ctrllimited="true" ctrlrange="-1 1"  gear="1"  joint="motor3_rot"/>
    <motor ctrllimited="true" ctrlrange="-1 1"  gear="1"  joint="motor4_rot"/>
    <motor ctrllimited="true" ctrlrange="-1 1"  gear="1"  joint="motor5_rot"/>
    <motor ctrllimited="true" ctrlrange="-1 1"  gear="1"  joint="motor6_rot"/>
    <motor ctrllimited="true" ctrlrange="-1 1"  gear="1"  joint="motor7_rot"/>
  </actuator>

</mujoco>
